INFO 2023-12-29 10:08:48,983 [root:accelerator.py:_autodetect_tpu_version:216]
Unable to poll TPU GCE metadata: HTTPConnectionPool(host='metadata.google.internal', port=80): Max retries exceeded with url: /computeMetadata/v1/instance/attributes/accelerator-type (Caused by NewConnectionError('<urllib3.connection.HTTPConnection object at 0x288134ee0>: Failed to establish a new connection: [Errno 8] nodename nor servname provided, or not known'))

INFO 2023-12-29 10:08:48,985 [root:accelerator.py:_autodetect_num_tpus:171]
Failed to detect number of TPUs: [Errno 2] No such file or directory: '/dev/vfio'

INFO 2023-12-29 10:10:27,480 [root:accelerator.py:_autodetect_tpu_version:216]
Unable to poll TPU GCE metadata: HTTPConnectionPool(host='metadata.google.internal', port=80): Max retries exceeded with url: /computeMetadata/v1/instance/attributes/accelerator-type (Caused by NewConnectionError('<urllib3.connection.HTTPConnection object at 0x16f1fcf40>: Failed to establish a new connection: [Errno 8] nodename nor servname provided, or not known'))

INFO 2023-12-29 10:10:27,480 [root:accelerator.py:_autodetect_num_tpus:171]
Failed to detect number of TPUs: [Errno 2] No such file or directory: '/dev/vfio'

